Workbook

Sheet Petunjuk
A1: Contoh Random Sampling — 38 Provinsi (rumus berjalan)
A3: Apa ini | B3: Workbook contoh yang mereproduksi engine Random Sampling Populi Center di Excel. Semua angka alokasi dihitung LEWAT RUMUS — ubah input, angka ikut berubah.
A4: Sumber data | B4: Sheet 'Referensi' = DPT & Penduduk 38 provinsi (data asli, non-PII, dari sampling-service/data/referensi_provinsi.csv).
A5: PENTING — MFD | B5: Sheet 'MFD' berisi SAMPEL DUMMY (nama desa 'DESA CONTOH ...') hanya agar rumus Kota/Desa & PPS menyala. GANTI seluruh isi sheet MFD dengan MFD BPS asli (kolom sama). Kolom J (PENDUDUK_DESA) opsional — syarat PPS self-weighting.
A6: Cara pakai | B6: 1) Buka sheet 'Parameter', isi sel kuning (target responden, responden/titik, minimum, basis). 2) Lihat 'Alokasi Proporsional' / 'Alokasi Akar-N' / 'PPS Sistematik'. 3) Ganti MFD dengan data asli bila ingin split Kota/Desa & PPS nyata.
A7: Legenda warna | B7: Kuning = sel input yang boleh Anda ubah. Hijau = link antar-sheet. Hitam = rumus.
A8: Metodologi | B8: Penjelasan rumus lengkap: docs/metodologi-sampling.md
A9: Catatan | B9: Excel dipakai untuk VERIFIKASI pola. Angka desa terpilih tak akan identik dengan generator (RNG numpy berbeda), tapi ALOKASI (jumlah titik per wilayah) sama persis karena deterministik.

Sheet Parameter
A1: Parameter Sampling
A3: Target responden (n_total) | B3: 1200
A4: Responden per titik (cluster_size) | B4: 10
A5: Minimum titik per provinsi (min_per_unit) | B5: 1
A6: Basis alokasi (PENDUDUK / DPT) | B6: PENDUDUK
A7: Jumlah provinsi | B7: =COUNTA(Referensi!B3:B40)
A8: Jumlah titik (n_titik = CEILING(n_total/cluster)) | B8: =CEILING(B3/B4,1)
A9: Sisa setelah minimum (= n_titik - min*Jumlah_prov) | B9: =B8-B5*B7

Sheet Referensi
A1: Referensi Provinsi (DPT & Penduduk) — data asli, non-PII
A2: NO | B2: NMPROP | C2: DPT | D2: PENDUDUK
A3: 1 | B3: ACEH | C3: 3742037 | D3: 5333733
A4: 2 | B4: SUMATERA UTARA | C4: 10853940 | D4: 14936148
A5: 3 | B5: SUMATERA BARAT | C5: 4088606 | D5: 5580232
A6: 4 | B6: RIAU | C6: 4732174 | D6: 6493603
A7: 5 | B7: JAMBI | C7: 2676107 | D7: 3585100
A8: 6 | B8: SUMATERA SELATAN | C8: 6326348 | D8: 8550849
A9: 7 | B9: BENGKULU | C9: 1494828 | D9: 2032940
A10: 8 | B10: LAMPUNG | C10: 6539128 | D10: 9081792
A11: 9 | B11: BANGKA BELITUNG | C11: 1067434 | D11: 1473100
A12: 10 | B12: KEPULAUAN RIAU | C12: 1500974 | D12: 2118239
A13: 11 | B13: DKI JAKARTA | C13: 8252897 | D13: 10609681
A14: 12 | B14: JAWA BARAT | C14: 35714901 | D14: 48782400
... A40: 38 | B40: PAPUA SELATAN | C40: 367269 | D40: 517623
B41: Sumber: sampling-service/data/referensi_provinsi.csv

Sheet MFD
A1: MFD — SAMPEL DUMMY (ganti dengan MFD BPS asli). 1 baris = 1 desa/kelurahan.
A2: KODEPROP | B2: KAB | C2: KEC | D2: DESA | E2: NMPROP | F2: NMKAB | G2: NMKEC | H2: NMDESA | I2: UR | J2: PENDUDUK_DESA
A3: 11 | B3: 2 | C3: 2 | D3: 1 | E3: ACEH | F3: KAB/KOTA CONTOH 2 | G3: KEC CONTOH 2 | H3: KELURAHAN CONTOH 01-001 | I3: 1 | J3: 764501
A4: 11 | B4: 3 | C4: 3 | D4: 2 | E4: ACEH | F4: KAB/KOTA CONTOH 3 | G4: KEC CONTOH 3 | H4: KELURAHAN CONTOH 01-002 | I4: 1 | J4: 995629
A5: 11 | B5: 4 | C5: 4 | D5: 3 | E5: ACEH | F5: KAB/KOTA CONTOH 4 | G5: KEC CONTOH 4 | H5: DESA CONTOH 01-003 | I5: 2 | J5: 1226757
A6: 11 | B6: 5 | C6: 5 | D6: 4 | E6: ACEH | F6: KAB/KOTA CONTOH 5 | G6: KEC CONTOH 5 | H6: DESA CONTOH 01-004 | I6: 2 | J6: 728943
A7: 11 | B7: 6 | C7: 6 | D7: 5 | E7: ACEH | F7: KAB/KOTA CONTOH 6 | G7: KEC CONTOH 6 | H7: DESA CONTOH 01-005 | I7: 2 | J7: 960071
A8: 11 | B8: 7 | C8: 7 | D8: 6 | E8: ACEH | F8: KAB/KOTA CONTOH 7 | G8: KEC CONTOH 7 | H8: DESA CONTOH 01-006 | I8: 2 | J8: 1191199
A9: 12 | B9: 2 | C9: 2 | D9: 1 | E9: SUMATERA UTARA | F9: KAB/KOTA CONTOH 2 | G9: KEC CONTOH 2 | H9: KELURAHAN CONTOH 02-001 | I9: 1 | J9: 1867018
A10: 12 | B10: 3 | C10: 3 | D10: 2 | E10: SUMATERA UTARA | F10: KAB/KOTA CONTOH 3 | G10: KEC CONTOH 3 | H10: KELURAHAN CONTOH 02-002 | I10: 1 | J10: 2352442
A11: 12 | B11: 4 | C11: 4 | D11: 3 | E11: SUMATERA UTARA | F11: KAB/KOTA CONTOH 4 | G11: KEC CONTOH 4 | H11: KELURAHAN CONTOH 02-003 | I11: 1 | J11: 1306912
A12: 12 | B12: 5 | C12: 5 | D12: 4 | E12: SUMATERA UTARA | F12: KAB/KOTA CONTOH 5 | G12: KEC CONTOH 5 | H12: DESA CONTOH 02-004 | I12: 2 | J12: 1792337
A13: 12 | B13: 6 | C13: 6 | D13: 5 | E13: SUMATERA UTARA | F13: KAB/KOTA CONTOH 6 | G13: KEC CONTOH 6 | H13: DESA CONTOH 02-005 | I13: 2 | J13: 2277761
A14: 12 | B14: 7 | C14: 7 | D14: 6 | E14: SUMATERA UTARA | F14: KAB/KOTA CONTOH 7 | G14: KEC CONTOH 7 | H14: DESA CONTOH 02-006 | I14: 2 | J14: 1232231
... A393: 48 | B393: 1 | C393: 10 | D393: 9 | E393: PAPUA SELATAN | F393: KAB/KOTA CONTOH 1 | G393: KEC CONTOH 10 | H393: DESA CONTOH 38-009 | I393: 2 | J393: 42559
E395: DUMMY — hapus & tempel MFD asli (kolom sama). UR: 1=Perkotaan, 2=Perdesaan. PENDUDUK_DESA (kolom J) opsional untuk PPS self-weighting.

Sheet Alokasi Proporsional
A1: Alokasi Proporsional + Jaminan Minimum (largest-remainder / Hamilton)
A3: Target responden (n_total) | B3: =Parameter!B3
A4: Responden per titik | B4: =Parameter!B4
A5: Jumlah titik (n_titik) | B5: =Parameter!B8
A6: Minimum per provinsi | B6: =Parameter!B5
A7: Sisa dibagi proporsional | B7: =Parameter!B9
A8: Sisa +1 (kurang) = Sisa - SUM(lantai) | B8: =B7-SUM(H11:H48)
A10: No | B10: Provinsi | C10: DPT | D10: Penduduk | E10: Ukuran | F10: Share | G10: Kuota | H10: Lantai | I10: Pecahan | J10: Rank | K10: +1 | L10: Titik | M10: Kota MFD | N10: Desa MFD | O10: Titik Kota | P10: Titik Desa | Q10: Responden
A11: =ROW()-10 | B11: =Referensi!B3 | C11: =Referensi!C3 | D11: =Referensi!D3 | E11: =IF(UPPER(Parameter!$B$6)="DPT",C11,D11) | F11: =E11/SUM(E$11:E$48) | G11: =$B$7*F11 | H11: =INT(G11) | I11: =G11-H11 | J11: =RANK(I11,$I$11:$I$48)+COUNTIF($I$11:I11,I11)-1 | K11: =IF(J11<=$B$8,1,0) | L11: =$B$6+H11+K11 | M11: =COUNTIFS(MFD!$E:$E,B11,MFD!$I:$I,1) | N11: =COUNTIFS(MFD!$E:$E,B11,MFD!$I:$I,2) | O11: =IF((M11+N11)=0,0,ROUND(L11*M11/(M11+N11),0)) | P11: =L11-O11 | Q11: =L11*Parameter!$B$4
A12: =ROW()-10 | B12: =Referensi!B4 | C12: =Referensi!C4 | D12: =Referensi!D4 | E12: =IF(UPPER(Parameter!$B$6)="DPT",C12,D12) | F12: =E12/SUM(E$11:E$48) | G12: =$B$7*F12 | H12: =INT(G12) | I12: =G12-H12 | J12: =RANK(I12,$I$11:$I$48)+COUNTIF($I$11:I12,I12)-1 | K12: =IF(J12<=$B$8,1,0) | L12: =$B$6+H12+K12 | M12: =COUNTIFS(MFD!$E:$E,B12,MFD!$I:$I,1) | N12: =COUNTIFS(MFD!$E:$E,B12,MFD!$I:$I,2) | O12: =IF((M12+N12)=0,0,ROUND(L12*M12/(M12+N12),0)) | P12: =L12-O12 | Q12: =L12*Parameter!$B$4
A13: =ROW()-10 | B13: =Referensi!B5 | C13: =Referensi!C5 | D13: =Referensi!D5 | E13: =IF(UPPER(Parameter!$B$6)="DPT",C13,D13) | F13: =E13/SUM(E$11:E$48) | G13: =$B$7*F13 | H13: =INT(G13) | I13: =G13-H13 | J13: =RANK(I13,$I$11:$I$48)+COUNTIF($I$11:I13,I13)-1 | K13: =IF(J13<=$B$8,1,0) | L13: =$B$6+H13+K13 | M13: =COUNTIFS(MFD!$E:$E,B13,MFD!$I:$I,1) | N13: =COUNTIFS(MFD!$E:$E,B13,MFD!$I:$I,2) | O13: =IF((M13+N13)=0,0,ROUND(L13*M13/(M13+N13),0)) | P13: =L13-O13 | Q13: =L13*Parameter!$B$4
A14: =ROW()-10 | B14: =Referensi!B6 | C14: =Referensi!C6 | D14: =Referensi!D6 | E14: =IF(UPPER(Parameter!$B$6)="DPT",C14,D14) | F14: =E14/SUM(E$11:E$48) | G14: =$B$7*F14 | H14: =INT(G14) | I14: =G14-H14 | J14: =RANK(I14,$I$11:$I$48)+COUNTIF($I$11:I14,I14)-1 | K14: =IF(J14<=$B$8,1,0) | L14: =$B$6+H14+K14 | M14: =COUNTIFS(MFD!$E:$E,B14,MFD!$I:$I,1) | N14: =COUNTIFS(MFD!$E:$E,B14,MFD!$I:$I,2) | O14: =IF((M14+N14)=0,0,ROUND(L14*M14/(M14+N14),0)) | P14: =L14-O14 | Q14: =L14*Parameter!$B$4
A15: =ROW()-10 | B15: =Referensi!B7 | C15: =Referensi!C7 | D15: =Referensi!D7 | E15: =IF(UPPER(Parameter!$B$6)="DPT",C15,D15) | F15: =E15/SUM(E$11:E$48) | G15: =$B$7*F15 | H15: =INT(G15) | I15: =G15-H15 | J15: =RANK(I15,$I$11:$I$48)+COUNTIF($I$11:I15,I15)-1 | K15: =IF(J15<=$B$8,1,0) | L15: =$B$6+H15+K15 | M15: =COUNTIFS(MFD!$E:$E,B15,MFD!$I:$I,1) | N15: =COUNTIFS(MFD!$E:$E,B15,MFD!$I:$I,2) | O15: =IF((M15+N15)=0,0,ROUND(L15*M15/(M15+N15),0)) | P15: =L15-O15 | Q15: =L15*Parameter!$B$4
A16: =ROW()-10 | B16: =Referensi!B8 | C16: =Referensi!C8 | D16: =Referensi!D8 | E16: =IF(UPPER(Parameter!$B$6)="DPT",C16,D16) | F16: =E16/SUM(E$11:E$48) | G16: =$B$7*F16 | H16: =INT(G16) | I16: =G16-H16 | J16: =RANK(I16,$I$11:$I$48)+COUNTIF($I$11:I16,I16)-1 | K16: =IF(J16<=$B$8,1,0) | L16: =$B$6+H16+K16 | M16: =COUNTIFS(MFD!$E:$E,B16,MFD!$I:$I,1) | N16: =COUNTIFS(MFD!$E:$E,B16,MFD!$I:$I,2) | O16: =IF((M16+N16)=0,0,ROUND(L16*M16/(M16+N16),0)) | P16: =L16-O16 | Q16: =L16*Parameter!$B$4
A17: =ROW()-10 | B17: =Referensi!B9 | C17: =Referensi!C9 | D17: =Referensi!D9 | E17: =IF(UPPER(Parameter!$B$6)="DPT",C17,D17) | F17: =E17/SUM(E$11:E$48) | G17: =$B$7*F17 | H17: =INT(G17) | I17: =G17-H17 | J17: =RANK(I17,$I$11:$I$48)+COUNTIF($I$11:I17,I17)-1 | K17: =IF(J17<=$B$8,1,0) | L17: =$B$6+H17+K17 | M17: =COUNTIFS(MFD!$E:$E,B17,MFD!$I:$I,1) | N17: =COUNTIFS(MFD!$E:$E,B17,MFD!$I:$I,2) | O17: =IF((M17+N17)=0,0,ROUND(L17*M17/(M17+N17),0)) | P17: =L17-O17 | Q17: =L17*Parameter!$B$4
A18: =ROW()-10 | B18: =Referensi!B10 | C18: =Referensi!C10 | D18: =Referensi!D10 | E18: =IF(UPPER(Parameter!$B$6)="DPT",C18,D18) | F18: =E18/SUM(E$11:E$48) | G18: =$B$7*F18 | H18: =INT(G18) | I18: =G18-H18 | J18: =RANK(I18,$I$11:$I$48)+COUNTIF($I$11:I18,I18)-1 | K18: =IF(J18<=$B$8,1,0) | L18: =$B$6+H18+K18 | M18: =COUNTIFS(MFD!$E:$E,B18,MFD!$I:$I,1) | N18: =COUNTIFS(MFD!$E:$E,B18,MFD!$I:$I,2) | O18: =IF((M18+N18)=0,0,ROUND(L18*M18/(M18+N18),0)) | P18: =L18-O18 | Q18: =L18*Parameter!$B$4
A19: =ROW()-10 | B19: =Referensi!B11 | C19: =Referensi!C11 | D19: =Referensi!D11 | E19: =IF(UPPER(Parameter!$B$6)="DPT",C19,D19) | F19: =E19/SUM(E$11:E$48) | G19: =$B$7*F19 | H19: =INT(G19) | I19: =G19-H19 | J19: =RANK(I19,$I$11:$I$48)+COUNTIF($I$11:I19,I19)-1 | K19: =IF(J19<=$B$8,1,0) | L19: =$B$6+H19+K19 | M19: =COUNTIFS(MFD!$E:$E,B19,MFD!$I:$I,1) | N19: =COUNTIFS(MFD!$E:$E,B19,MFD!$I:$I,2) | O19: =IF((M19+N19)=0,0,ROUND(L19*M19/(M19+N19),0)) | P19: =L19-O19 | Q19: =L19*Parameter!$B$4
A20: =ROW()-10 | B20: =Referensi!B12 | C20: =Referensi!C12 | D20: =Referensi!D12 | E20: =IF(UPPER(Parameter!$B$6)="DPT",C20,D20) | F20: =E20/SUM(E$11:E$48) | G20: =$B$7*F20 | H20: =INT(G20) | I20: =G20-H20 | J20: =RANK(I20,$I$11:$I$48)+COUNTIF($I$11:I20,I20)-1 | K20: =IF(J20<=$B$8,1,0) | L20: =$B$6+H20+K20 | M20: =COUNTIFS(MFD!$E:$E,B20,MFD!$I:$I,1) | N20: =COUNTIFS(MFD!$E:$E,B20,MFD!$I:$I,2) | O20: =IF((M20+N20)=0,0,ROUND(L20*M20/(M20+N20),0)) | P20: =L20-O20 | Q20: =L20*Parameter!$B$4
A21: =ROW()-10 | B21: =Referensi!B13 | C21: =Referensi!C13 | D21: =Referensi!D13 | E21: =IF(UPPER(Parameter!$B$6)="DPT",C21,D21) | F21: =E21/SUM(E$11:E$48) | G21: =$B$7*F21 | H21: =INT(G21) | I21: =G21-H21 | J21: =RANK(I21,$I$11:$I$48)+COUNTIF($I$11:I21,I21)-1 | K21: =IF(J21<=$B$8,1,0) | L21: =$B$6+H21+K21 | M21: =COUNTIFS(MFD!$E:$E,B21,MFD!$I:$I,1) | N21: =COUNTIFS(MFD!$E:$E,B21,MFD!$I:$I,2) | O21: =IF((M21+N21)=0,0,ROUND(L21*M21/(M21+N21),0)) | P21: =L21-O21 | Q21: =L21*Parameter!$B$4
A22: =ROW()-10 | B22: =Referensi!B14 | C22: =Referensi!C14 | D22: =Referensi!D14 | E22: =IF(UPPER(Parameter!$B$6)="DPT",C22,D22) | F22: =E22/SUM(E$11:E$48) | G22: =$B$7*F22 | H22: =INT(G22) | I22: =G22-H22 | J22: =RANK(I22,$I$11:$I$48)+COUNTIF($I$11:I22,I22)-1 | K22: =IF(J22<=$B$8,1,0) | L22: =$B$6+H22+K22 | M22: =COUNTIFS(MFD!$E:$E,B22,MFD!$I:$I,1) | N22: =COUNTIFS(MFD!$E:$E,B22,MFD!$I:$I,2) | O22: =IF((M22+N22)=0,0,ROUND(L22*M22/(M22+N22),0)) | P22: =L22-O22 | Q22: =L22*Parameter!$B$4
... A48: =ROW()-10 | B48: =Referensi!B40 | C48: =Referensi!C40 | D48: =Referensi!D40 | E48: =IF(UPPER(Parameter!$B$6)="DPT",C48,D48) | F48: =E48/SUM(E$11:E$48) | G48: =$B$7*F48 | H48: =INT(G48) | I48: =G48-H48 | J48: =RANK(I48,$I$11:$I$48)+COUNTIF($I$11:I48,I48)-1 | K48: =IF(J48<=$B$8,1,0) | L48: =$B$6+H48+K48 | M48: =COUNTIFS(MFD!$E:$E,B48,MFD!$I:$I,1) | N48: =COUNTIFS(MFD!$E:$E,B48,MFD!$I:$I,2) | O48: =IF((M48+N48)=0,0,ROUND(L48*M48/(M48+N48),0)) | P48: =L48-O48 | Q48: =L48*Parameter!$B$4
B49: TOTAL | C49: =SUM(C11:C48) | D49: =SUM(D11:D48) | E49: =SUM(E11:E48) | F49: =SUM(F11:F48) | L49: =SUM(L11:L48) | M49: =SUM(M11:M48) | N49: =SUM(N11:N48) | O49: =SUM(O11:O48) | P49: =SUM(P11:P48) | Q49: =SUM(Q11:Q48)
B51: Cek: kolom 'Titik' TOTAL harus = n_titik. 'Responden' TOTAL = n_titik×cluster (≥ n_total; engine memangkas titik terakhir agar pas).

Sheet Alokasi Akar-N
A1: Alokasi Akar-Kuadrat (√N) + Bobot Desain
A3: Jumlah titik (n_titik) | B3: =Parameter!B8
A4: Minimum per provinsi | B4: =Parameter!B5
A5: Sisa dibagi proporsional | B5: =Parameter!B9
A6: Sisa +1 (kurang) = Sisa - SUM(lantai) | B6: =B5-SUM(I11:I48)
A10: No | B10: Provinsi | C10: DPT | D10: Penduduk | E10: Ukuran | F10: √Ukuran | G10: Share | H10: Kuota | I10: Lantai | J10: Pecahan | K10: Rank | L10: +1 | M10: Titik | N10: SharePop | O10: Bobot Desain | P10: Responden
A11: =ROW()-10 | B11: =Referensi!B3 | C11: =Referensi!C3 | D11: =Referensi!D3 | E11: =IF(UPPER(Parameter!$B$6)="DPT",C11,D11) | F11: =SQRT(E11) | G11: =F11/SUM(F$11:F$48) | H11: =$B$5*G11 | I11: =INT(H11) | J11: =H11-I11 | K11: =RANK(J11,$J$11:$J$48)+COUNTIF($J$11:J11,J11)-1 | L11: =IF(K11<=$B$6,1,0) | M11: =Parameter!$B$5+I11+L11 | N11: =E11/SUM(E$11:E$48) | O11: =IF(M11=0,"",N11/(M11/SUM(M$11:M$48))) | P11: =M11*Parameter!$B$4
A12: =ROW()-10 | B12: =Referensi!B4 | C12: =Referensi!C4 | D12: =Referensi!D4 | E12: =IF(UPPER(Parameter!$B$6)="DPT",C12,D12) | F12: =SQRT(E12) | G12: =F12/SUM(F$11:F$48) | H12: =$B$5*G12 | I12: =INT(H12) | J12: =H12-I12 | K12: =RANK(J12,$J$11:$J$48)+COUNTIF($J$11:J12,J12)-1 | L12: =IF(K12<=$B$6,1,0) | M12: =Parameter!$B$5+I12+L12 | N12: =E12/SUM(E$11:E$48) | O12: =IF(M12=0,"",N12/(M12/SUM(M$11:M$48))) | P12: =M12*Parameter!$B$4
A13: =ROW()-10 | B13: =Referensi!B5 | C13: =Referensi!C5 | D13: =Referensi!D5 | E13: =IF(UPPER(Parameter!$B$6)="DPT",C13,D13) | F13: =SQRT(E13) | G13: =F13/SUM(F$11:F$48) | H13: =$B$5*G13 | I13: =INT(H13) | J13: =H13-I13 | K13: =RANK(J13,$J$11:$J$48)+COUNTIF($J$11:J13,J13)-1 | L13: =IF(K13<=$B$6,1,0) | M13: =Parameter!$B$5+I13+L13 | N13: =E13/SUM(E$11:E$48) | O13: =IF(M13=0,"",N13/(M13/SUM(M$11:M$48))) | P13: =M13*Parameter!$B$4
A14: =ROW()-10 | B14: =Referensi!B6 | C14: =Referensi!C6 | D14: =Referensi!D6 | E14: =IF(UPPER(Parameter!$B$6)="DPT",C14,D14) | F14: =SQRT(E14) | G14: =F14/SUM(F$11:F$48) | H14: =$B$5*G14 | I14: =INT(H14) | J14: =H14-I14 | K14: =RANK(J14,$J$11:$J$48)+COUNTIF($J$11:J14,J14)-1 | L14: =IF(K14<=$B$6,1,0) | M14: =Parameter!$B$5+I14+L14 | N14: =E14/SUM(E$11:E$48) | O14: =IF(M14=0,"",N14/(M14/SUM(M$11:M$48))) | P14: =M14*Parameter!$B$4
A15: =ROW()-10 | B15: =Referensi!B7 | C15: =Referensi!C7 | D15: =Referensi!D7 | E15: =IF(UPPER(Parameter!$B$6)="DPT",C15,D15) | F15: =SQRT(E15) | G15: =F15/SUM(F$11:F$48) | H15: =$B$5*G15 | I15: =INT(H15) | J15: =H15-I15 | K15: =RANK(J15,$J$11:$J$48)+COUNTIF($J$11:J15,J15)-1 | L15: =IF(K15<=$B$6,1,0) | M15: =Parameter!$B$5+I15+L15 | N15: =E15/SUM(E$11:E$48) | O15: =IF(M15=0,"",N15/(M15/SUM(M$11:M$48))) | P15: =M15*Parameter!$B$4
A16: =ROW()-10 | B16: =Referensi!B8 | C16: =Referensi!C8 | D16: =Referensi!D8 | E16: =IF(UPPER(Parameter!$B$6)="DPT",C16,D16) | F16: =SQRT(E16) | G16: =F16/SUM(F$11:F$48) | H16: =$B$5*G16 | I16: =INT(H16) | J16: =H16-I16 | K16: =RANK(J16,$J$11:$J$48)+COUNTIF($J$11:J16,J16)-1 | L16: =IF(K16<=$B$6,1,0) | M16: =Parameter!$B$5+I16+L16 | N16: =E16/SUM(E$11:E$48) | O16: =IF(M16=0,"",N16/(M16/SUM(M$11:M$48))) | P16: =M16*Parameter!$B$4
A17: =ROW()-10 | B17: =Referensi!B9 | C17: =Referensi!C9 | D17: =Referensi!D9 | E17: =IF(UPPER(Parameter!$B$6)="DPT",C17,D17) | F17: =SQRT(E17) | G17: =F17/SUM(F$11:F$48) | H17: =$B$5*G17 | I17: =INT(H17) | J17: =H17-I17 | K17: =RANK(J17,$J$11:$J$48)+COUNTIF($J$11:J17,J17)-1 | L17: =IF(K17<=$B$6,1,0) | M17: =Parameter!$B$5+I17+L17 | N17: =E17/SUM(E$11:E$48) | O17: =IF(M17=0,"",N17/(M17/SUM(M$11:M$48))) | P17: =M17*Parameter!$B$4
A18: =ROW()-10 | B18: =Referensi!B10 | C18: =Referensi!C10 | D18: =Referensi!D10 | E18: =IF(UPPER(Parameter!$B$6)="DPT",C18,D18) | F18: =SQRT(E18) | G18: =F18/SUM(F$11:F$48) | H18: =$B$5*G18 | I18: =INT(H18) | J18: =H18-I18 | K18: =RANK(J18,$J$11:$J$48)+COUNTIF($J$11:J18,J18)-1 | L18: =IF(K18<=$B$6,1,0) | M18: =Parameter!$B$5+I18+L18 | N18: =E18/SUM(E$11:E$48) | O18: =IF(M18=0,"",N18/(M18/SUM(M$11:M$48))) | P18: =M18*Parameter!$B$4
A19: =ROW()-10 | B19: =Referensi!B11 | C19: =Referensi!C11 | D19: =Referensi!D11 | E19: =IF(UPPER(Parameter!$B$6)="DPT",C19,D19) | F19: =SQRT(E19) | G19: =F19/SUM(F$11:F$48) | H19: =$B$5*G19 | I19: =INT(H19) | J19: =H19-I19 | K19: =RANK(J19,$J$11:$J$48)+COUNTIF($J$11:J19,J19)-1 | L19: =IF(K19<=$B$6,1,0) | M19: =Parameter!$B$5+I19+L19 | N19: =E19/SUM(E$11:E$48) | O19: =IF(M19=0,"",N19/(M19/SUM(M$11:M$48))) | P19: =M19*Parameter!$B$4
A20: =ROW()-10 | B20: =Referensi!B12 | C20: =Referensi!C12 | D20: =Referensi!D12 | E20: =IF(UPPER(Parameter!$B$6)="DPT",C20,D20) | F20: =SQRT(E20) | G20: =F20/SUM(F$11:F$48) | H20: =$B$5*G20 | I20: =INT(H20) | J20: =H20-I20 | K20: =RANK(J20,$J$11:$J$48)+COUNTIF($J$11:J20,J20)-1 | L20: =IF(K20<=$B$6,1,0) | M20: =Parameter!$B$5+I20+L20 | N20: =E20/SUM(E$11:E$48) | O20: =IF(M20=0,"",N20/(M20/SUM(M$11:M$48))) | P20: =M20*Parameter!$B$4
A21: =ROW()-10 | B21: =Referensi!B13 | C21: =Referensi!C13 | D21: =Referensi!D13 | E21: =IF(UPPER(Parameter!$B$6)="DPT",C21,D21) | F21: =SQRT(E21) | G21: =F21/SUM(F$11:F$48) | H21: =$B$5*G21 | I21: =INT(H21) | J21: =H21-I21 | K21: =RANK(J21,$J$11:$J$48)+COUNTIF($J$11:J21,J21)-1 | L21: =IF(K21<=$B$6,1,0) | M21: =Parameter!$B$5+I21+L21 | N21: =E21/SUM(E$11:E$48) | O21: =IF(M21=0,"",N21/(M21/SUM(M$11:M$48))) | P21: =M21*Parameter!$B$4
A22: =ROW()-10 | B22: =Referensi!B14 | C22: =Referensi!C14 | D22: =Referensi!D14 | E22: =IF(UPPER(Parameter!$B$6)="DPT",C22,D22) | F22: =SQRT(E22) | G22: =F22/SUM(F$11:F$48) | H22: =$B$5*G22 | I22: =INT(H22) | J22: =H22-I22 | K22: =RANK(J22,$J$11:$J$48)+COUNTIF($J$11:J22,J22)-1 | L22: =IF(K22<=$B$6,1,0) | M22: =Parameter!$B$5+I22+L22 | N22: =E22/SUM(E$11:E$48) | O22: =IF(M22=0,"",N22/(M22/SUM(M$11:M$48))) | P22: =M22*Parameter!$B$4
... A48: =ROW()-10 | B48: =Referensi!B40 | C48: =Referensi!C40 | D48: =Referensi!D40 | E48: =IF(UPPER(Parameter!$B$6)="DPT",C48,D48) | F48: =SQRT(E48) | G48: =F48/SUM(F$11:F$48) | H48: =$B$5*G48 | I48: =INT(H48) | J48: =H48-I48 | K48: =RANK(J48,$J$11:$J$48)+COUNTIF($J$11:J48,J48)-1 | L48: =IF(K48<=$B$6,1,0) | M48: =Parameter!$B$5+I48+L48 | N48: =E48/SUM(E$11:E$48) | O48: =IF(M48=0,"",N48/(M48/SUM(M$11:M$48))) | P48: =M48*Parameter!$B$4
B49: TOTAL | C49: =SUM(C11:C48) | D49: =SUM(D11:D48) | E49: =SUM(E11:E48) | G49: =SUM(G11:G48) | M49: =SUM(M11:M48) | P49: =SUM(P11:P48)
B51: Bobot Desain = share populasi ÷ share titik. Pakai sebagai weight di SPSS/R. Proporsional murni → ≈1; √N → menyimpang (mengoreksi oversample wilayah kecil).

Sheet PPS Sistematik
A1: PPS Sistematik (ilustrasi) — desa diurut, ukuran dikumulatif, titik tiap interval tetap
A3: No | B3: Provinsi | C3: Desa | D3: Ukuran | E3: Kumulatif | G3: Jumlah titik (n_titik) | H3: =Parameter!B8
A4: =ROW()-3 | B4: =MFD!E3 | C4: =MFD!H3 | D4: =MFD!J3 | E4: =D4 | G4: Total ukuran | H4: =E394
A5: =ROW()-3 | B5: =MFD!E4 | C5: =MFD!H4 | D5: =MFD!J4 | E5: =E4+D5 | G5: Interval I = Total / n_titik | H5: =H4/H3
A6: =ROW()-3 | B6: =MFD!E5 | C6: =MFD!H5 | D6: =MFD!J5 | E6: =E5+D6 | G6: Awalan (start) — input, default I/2 | H6: =H5/2
A7: =ROW()-3 | B7: =MFD!E6 | C7: =MFD!H6 | D7: =MFD!J6 | E7: =E6+D7
A8: =ROW()-3 | B8: =MFD!E7 | C8: =MFD!H7 | D8: =MFD!J7 | E8: =E7+D8 | G8: Titik sistematik terpilih (p_k = start + k·I)
A9: =ROW()-3 | B9: =MFD!E8 | C9: =MFD!H8 | D9: =MFD!J8 | E9: =E8+D9 | G9: k | H9: p_k | I9: Idx Desa | J9: Provinsi | K9: Desa Terpilih
A10: =ROW()-3 | B10: =MFD!E9 | C10: =MFD!H9 | D10: =MFD!J9 | E10: =E9+D10 | G10: 0 | H10: =IF(0<$H$3,$H$6+0*$H$5,"") | I10: =IF(H10="","",MIN(391,MATCH(H10,$E$4:$E$394,1)+1)) | J10: =IF(I10="","",INDEX($B$4:$B$394,I10)) | K10: =IF(I10="","",INDEX($C$4:$C$394,I10))
A11: =ROW()-3 | B11: =MFD!E10 | C11: =MFD!H10 | D11: =MFD!J10 | E11: =E10+D11 | G11: 1 | H11: =IF(1<$H$3,$H$6+1*$H$5,"") | I11: =IF(H11="","",MIN(391,MATCH(H11,$E$4:$E$394,1)+1)) | J11: =IF(I11="","",INDEX($B$4:$B$394,I11)) | K11: =IF(I11="","",INDEX($C$4:$C$394,I11))
A12: =ROW()-3 | B12: =MFD!E11 | C12: =MFD!H11 | D12: =MFD!J11 | E12: =E11+D12 | G12: 2 | H12: =IF(2<$H$3,$H$6+2*$H$5,"") | I12: =IF(H12="","",MIN(391,MATCH(H12,$E$4:$E$394,1)+1)) | J12: =IF(I12="","",INDEX($B$4:$B$394,I12)) | K12: =IF(I12="","",INDEX($C$4:$C$394,I12))
A13: =ROW()-3 | B13: =MFD!E12 | C13: =MFD!H12 | D13: =MFD!J12 | E13: =E12+D13 | G13: 3 | H13: =IF(3<$H$3,$H$6+3*$H$5,"") | I13: =IF(H13="","",MIN(391,MATCH(H13,$E$4:$E$394,1)+1)) | J13: =IF(I13="","",INDEX($B$4:$B$394,I13)) | K13: =IF(I13="","",INDEX($C$4:$C$394,I13))
A14: =ROW()-3 | B14: =MFD!E13 | C14: =MFD!H13 | D14: =MFD!J13 | E14: =E13+D14 | G14: 4 | H14: =IF(4<$H$3,$H$6+4*$H$5,"") | I14: =IF(H14="","",MIN(391,MATCH(H14,$E$4:$E$394,1)+1)) | J14: =IF(I14="","",INDEX($B$4:$B$394,I14)) | K14: =IF(I14="","",INDEX($C$4:$C$394,I14))
A15: =ROW()-3 | B15: =MFD!E14 | C15: =MFD!H14 | D15: =MFD!J14 | E15: =E14+D15 | G15: 5 | H15: =IF(5<$H$3,$H$6+5*$H$5,"") | I15: =IF(H15="","",MIN(391,MATCH(H15,$E$4:$E$394,1)+1)) | J15: =IF(I15="","",INDEX($B$4:$B$394,I15)) | K15: =IF(I15="","",INDEX($C$4:$C$394,I15))
A16: =ROW()-3 | B16: =MFD!E15 | C16: =MFD!H15 | D16: =MFD!J15 | E16: =E15+D16 | G16: 6 | H16: =IF(6<$H$3,$H$6+6*$H$5,"") | I16: =IF(H16="","",MIN(391,MATCH(H16,$E$4:$E$394,1)+1)) | J16: =IF(I16="","",INDEX($B$4:$B$394,I16)) | K16: =IF(I16="","",INDEX($C$4:$C$394,I16))
A17: =ROW()-3 | B17: =MFD!E16 | C17: =MFD!H16 | D17: =MFD!J16 | E17: =E16+D17 | G17: 7 | H17: =IF(7<$H$3,$H$6+7*$H$5,"") | I17: =IF(H17="","",MIN(391,MATCH(H17,$E$4:$E$394,1)+1)) | J17: =IF(I17="","",INDEX($B$4:$B$394,I17)) | K17: =IF(I17="","",INDEX($C$4:$C$394,I17))
A18: =ROW()-3 | B18: =MFD!E17 | C18: =MFD!H17 | D18: =MFD!J17 | E18: =E17+D18 | G18: 8 | H18: =IF(8<$H$3,$H$6+8*$H$5,"") | I18: =IF(H18="","",MIN(391,MATCH(H18,$E$4:$E$394,1)+1)) | J18: =IF(I18="","",INDEX($B$4:$B$394,I18)) | K18: =IF(I18="","",INDEX($C$4:$C$394,I18))
A19: =ROW()-3 | B19: =MFD!E18 | C19: =MFD!H18 | D19: =MFD!J18 | E19: =E18+D19 | G19: 9 | H19: =IF(9<$H$3,$H$6+9*$H$5,"") | I19: =IF(H19="","",MIN(391,MATCH(H19,$E$4:$E$394,1)+1)) | J19: =IF(I19="","",INDEX($B$4:$B$394,I19)) | K19: =IF(I19="","",INDEX($C$4:$C$394,I19))
A20: =ROW()-3 | B20: =MFD!E19 | C20: =MFD!H19 | D20: =MFD!J19 | E20: =E19+D20 | G20: 10 | H20: =IF(10<$H$3,$H$6+10*$H$5,"") | I20: =IF(H20="","",MIN(391,MATCH(H20,$E$4:$E$394,1)+1)) | J20: =IF(I20="","",INDEX($B$4:$B$394,I20)) | K20: =IF(I20="","",INDEX($C$4:$C$394,I20))
A21: =ROW()-3 | B21: =MFD!E20 | C21: =MFD!H20 | D21: =MFD!J20 | E21: =E20+D21 | G21: 11 | H21: =IF(11<$H$3,$H$6+11*$H$5,"") | I21: =IF(H21="","",MIN(391,MATCH(H21,$E$4:$E$394,1)+1)) | J21: =IF(I21="","",INDEX($B$4:$B$394,I21)) | K21: =IF(I21="","",INDEX($C$4:$C$394,I21))
A22: =ROW()-3 | B22: =MFD!E21 | C22: =MFD!H21 | D22: =MFD!J21 | E22: =E21+D22 | G22: 12 | H22: =IF(12<$H$3,$H$6+12*$H$5,"") | I22: =IF(H22="","",MIN(391,MATCH(H22,$E$4:$E$394,1)+1)) | J22: =IF(I22="","",INDEX($B$4:$B$394,I22)) | K22: =IF(I22="","",INDEX($C$4:$C$394,I22))
A23: =ROW()-3 | B23: =MFD!E22 | C23: =MFD!H22 | D23: =MFD!J22 | E23: =E22+D23 | G23: 13 | H23: =IF(13<$H$3,$H$6+13*$H$5,"") | I23: =IF(H23="","",MIN(391,MATCH(H23,$E$4:$E$394,1)+1)) | J23: =IF(I23="","",INDEX($B$4:$B$394,I23)) | K23: =IF(I23="","",INDEX($C$4:$C$394,I23))
A24: =ROW()-3 | B24: =MFD!E23 | C24: =MFD!H23 | D24: =MFD!J23 | E24: =E23+D24 | G24: 14 | H24: =IF(14<$H$3,$H$6+14*$H$5,"") | I24: =IF(H24="","",MIN(391,MATCH(H24,$E$4:$E$394,1)+1)) | J24: =IF(I24="","",INDEX($B$4:$B$394,I24)) | K24: =IF(I24="","",INDEX($C$4:$C$394,I24))
A25: =ROW()-3 | B25: =MFD!E24 | C25: =MFD!H24 | D25: =MFD!J24 | E25: =E24+D25 | G25: 15 | H25: =IF(15<$H$3,$H$6+15*$H$5,"") | I25: =IF(H25="","",MIN(391,MATCH(H25,$E$4:$E$394,1)+1)) | J25: =IF(I25="","",INDEX($B$4:$B$394,I25)) | K25: =IF(I25="","",INDEX($C$4:$C$394,I25))
A26: =ROW()-3 | B26: =MFD!E25 | C26: =MFD!H25 | D26: =MFD!J25 | E26: =E25+D26 | G26: 16 | H26: =IF(16<$H$3,$H$6+16*$H$5,"") | I26: =IF(H26="","",MIN(391,MATCH(H26,$E$4:$E$394,1)+1)) | J26: =IF(I26="","",INDEX($B$4:$B$394,I26)) | K26: =IF(I26="","",INDEX($C$4:$C$394,I26))
A27: =ROW()-3 | B27: =MFD!E26 | C27: =MFD!H26 | D27: =MFD!J26 | E27: =E26+D27 | G27: 17 | H27: =IF(17<$H$3,$H$6+17*$H$5,"") | I27: =IF(H27="","",MIN(391,MATCH(H27,$E$4:$E$394,1)+1)) | J27: =IF(I27="","",INDEX($B$4:$B$394,I27)) | K27: =IF(I27="","",INDEX($C$4:$C$394,I27))
A28: =ROW()-3 | B28: =MFD!E27 | C28: =MFD!H27 | D28: =MFD!J27 | E28: =E27+D28 | G28: 18 | H28: =IF(18<$H$3,$H$6+18*$H$5,"") | I28: =IF(H28="","",MIN(391,MATCH(H28,$E$4:$E$394,1)+1)) | J28: =IF(I28="","",INDEX($B$4:$B$394,I28)) | K28: =IF(I28="","",INDEX($C$4:$C$394,I28))
A29: =ROW()-3 | B29: =MFD!E28 | C29: =MFD!H28 | D29: =MFD!J28 | E29: =E28+D29 | G29: 19 | H29: =IF(19<$H$3,$H$6+19*$H$5,"") | I29: =IF(H29="","",MIN(391,MATCH(H29,$E$4:$E$394,1)+1)) | J29: =IF(I29="","",INDEX($B$4:$B$394,I29)) | K29: =IF(I29="","",INDEX($C$4:$C$394,I29))
A30: =ROW()-3 | B30: =MFD!E29 | C30: =MFD!H29 | D30: =MFD!J29 | E30: =E29+D30 | G30: 20 | H30: =IF(20<$H$3,$H$6+20*$H$5,"") | I30: =IF(H30="","",MIN(391,MATCH(H30,$E$4:$E$394,1)+1)) | J30: =IF(I30="","",INDEX($B$4:$B$394,I30)) | K30: =IF(I30="","",INDEX($C$4:$C$394,I30))
A31: =ROW()-3 | B31: =MFD!E30 | C31: =MFD!H30 | D31: =MFD!J30 | E31: =E30+D31 | G31: 21 | H31: =IF(21<$H$3,$H$6+21*$H$5,"") | I31: =IF(H31="","",MIN(391,MATCH(H31,$E$4:$E$394,1)+1)) | J31: =IF(I31="","",INDEX($B$4:$B$394,I31)) | K31: =IF(I31="","",INDEX($C$4:$C$394,I31))
A32: =ROW()-3 | B32: =MFD!E31 | C32: =MFD!H31 | D32: =MFD!J31 | E32: =E31+D32 | G32: 22 | H32: =IF(22<$H$3,$H$6+22*$H$5,"") | I32: =IF(H32="","",MIN(391,MATCH(H32,$E$4:$E$394,1)+1)) | J32: =IF(I32="","",INDEX($B$4:$B$394,I32)) | K32: =IF(I32="","",INDEX($C$4:$C$394,I32))
A33: =ROW()-3 | B33: =MFD!E32 | C33: =MFD!H32 | D33: =MFD!J32 | E33: =E32+D33 | G33: 23 | H33: =IF(23<$H$3,$H$6+23*$H$5,"") | I33: =IF(H33="","",MIN(391,MATCH(H33,$E$4:$E$394,1)+1)) | J33: =IF(I33="","",INDEX($B$4:$B$394,I33)) | K33: =IF(I33="","",INDEX($C$4:$C$394,I33))
A34: =ROW()-3 | B34: =MFD!E33 | C34: =MFD!H33 | D34: =MFD!J33 | E34: =E33+D34 | G34: 24 | H34: =IF(24<$H$3,$H$6+24*$H$5,"") | I34: =IF(H34="","",MIN(391,MATCH(H34,$E$4:$E$394,1)+1)) | J34: =IF(I34="","",INDEX($B$4:$B$394,I34)) | K34: =IF(I34="","",INDEX($C$4:$C$394,I34))
A35: =ROW()-3 | B35: =MFD!E34 | C35: =MFD!H34 | D35: =MFD!J34 | E35: =E34+D35 | G35: 25 | H35: =IF(25<$H$3,$H$6+25*$H$5,"") | I35: =IF(H35="","",MIN(391,MATCH(H35,$E$4:$E$394,1)+1)) | J35: =IF(I35="","",INDEX($B$4:$B$394,I35)) | K35: =IF(I35="","",INDEX($C$4:$C$394,I35))
A36: =ROW()-3 | B36: =MFD!E35 | C36: =MFD!H35 | D36: =MFD!J35 | E36: =E35+D36 | G36: 26 | H36: =IF(26<$H$3,$H$6+26*$H$5,"") | I36: =IF(H36="","",MIN(391,MATCH(H36,$E$4:$E$394,1)+1)) | J36: =IF(I36="","",INDEX($B$4:$B$394,I36)) | K36: =IF(I36="","",INDEX($C$4:$C$394,I36))
A37: =ROW()-3 | B37: =MFD!E36 | C37: =MFD!H36 | D37: =MFD!J36 | E37: =E36+D37 | G37: 27 | H37: =IF(27<$H$3,$H$6+27*$H$5,"") | I37: =IF(H37="","",MIN(391,MATCH(H37,$E$4:$E$394,1)+1)) | J37: =IF(I37="","",INDEX($B$4:$B$394,I37)) | K37: =IF(I37="","",INDEX($C$4:$C$394,I37))
A38: =ROW()-3 | B38: =MFD!E37 | C38: =MFD!H37 | D38: =MFD!J37 | E38: =E37+D38 | G38: 28 | H38: =IF(28<$H$3,$H$6+28*$H$5,"") | I38: =IF(H38="","",MIN(391,MATCH(H38,$E$4:$E$394,1)+1)) | J38: =IF(I38="","",INDEX($B$4:$B$394,I38)) | K38: =IF(I38="","",INDEX($C$4:$C$394,I38))
A39: =ROW()-3 | B39: =MFD!E38 | C39: =MFD!H38 | D39: =MFD!J38 | E39: =E38+D39 | G39: 29 | H39: =IF(29<$H$3,$H$6+29*$H$5,"") | I39: =IF(H39="","",MIN(391,MATCH(H39,$E$4:$E$394,1)+1)) | J39: =IF(I39="","",INDEX($B$4:$B$394,I39)) | K39: =IF(I39="","",INDEX($C$4:$C$394,I39))
A40: =ROW()-3 | B40: =MFD!E39 | C40: =MFD!H39 | D40: =MFD!J39 | E40: =E39+D40 | G40: 30 | H40: =IF(30<$H$3,$H$6+30*$H$5,"") | I40: =IF(H40="","",MIN(391,MATCH(H40,$E$4:$E$394,1)+1)) | J40: =IF(I40="","",INDEX($B$4:$B$394,I40)) | K40: =IF(I40="","",INDEX($C$4:$C$394,I40))
A41: =ROW()-3 | B41: =MFD!E40 | C41: =MFD!H40 | D41: =MFD!J40 | E41: =E40+D41 | G41: 31 | H41: =IF(31<$H$3,$H$6+31*$H$5,"") | I41: =IF(H41="","",MIN(391,MATCH(H41,$E$4:$E$394,1)+1)) | J41: =IF(I41="","",INDEX($B$4:$B$394,I41)) | K41: =IF(I41="","",INDEX($C$4:$C$394,I41))
...
